Workbook

Sheet Welcome
B2: SOFTWARE BY LEARN AND GROW RICH
B3: The personal finance database for the path to peace and prosperity.
B5: WELCOME
B6: This is the database. You won't usually live here. The app pulls everything from this file and shows you only what matters: your numbers, your dream, your gap, your next move.
B8: If you're seeing this directly, that's fine too. Every tab below is built so you can read it, edit it, and understand it.
B10: HOW IT FLOWS
B11: 1. Setup & Profiles — Tell us who you are. (One-time, 5 minutes.)
B12: 2. Categories — Pre-loaded. Edit if you want, leave as-is if you don't.
B13: 3. Income Log + Expense Log — Where money in and money out gets recorded. 30 seconds per entry.
B14: 4. Assets Register + Liabilities Register — What you own and what owns you.
B15: 5. Vision (His / Hers / Joint) — Your Dream Life Number. The destination.
B16: 6. Best Year Ever — The plan to close the gap, one year at a time.
... B30: Zach

Sheet Setup & Profiles
B2: SETUP & PROFILES
B3: Tell us who you are. The whole tool reads from these answers.
B5: SPOUSE 1 (HIS) | E5: SPOUSE 2 (HERS)
B6: Name | C6: Zach | E6: Name | F6: Sumary
B7: Age | C7: 40 | E7: Age | F7: 38
B8: Role / Occupation | C8: Founder, Learn And Grow Rich | E8: Role / Occupation | F8: Co-creator
B9: Country | C9: USA | E9: Country | F9: USA
B10: Currency | C10: USD | E10: Currency | F10: USD
B11: Tax Filing Status | C11: Married Filing Jointly | E11: Tax Filing Status | F11: Married Filing Jointly
B12: Start Date | C12: 46023 | E12: Start Date | F12: 46023
B14: JOINT HOUSEHOLD
B15: Household Name | C15: The Oehlmans
B16: Primary Residence | C16: United States
B17: Children / Dependents | C17: 0
B18: Currency for Reporting | C18: USD
B20: The 'Owner' field on every transaction in the Income Log and Expense Log uses these names: His, Hers, Joint. Three lenses on one household.

Sheet Categories
B2: CATEGORIES
B3: The library. Every income, expense, asset, and liability gets one of these tags.
B5: INCOME CATEGORIES
B6: Category Name | C6: Description | D6: Default Owner
B7: Active Income | C7: Wages, salary, contract pay, 1099 income — money you trade time for. | D7: Joint
B8: Business Income | C8: Profit distributions, owner draws, dividends from businesses you own. | D8: Joint
B9: Passive Income | C9: Rental income, dividends, interest, royalties — money that arrives without your time. | D9: Joint
B10: Side Income | C10: Side hustles, occasional gigs, project work outside the main job. | D10: Joint
B11: Investment Gains | C11: Realized gains from selling stocks, crypto, or other investments. | D11: Joint
B12: Gifts & Windfalls | C12: Inheritances, gifts, prizes, tax refunds, one-time money in. | D12: Joint
B13: Other Income | C13: Anything that doesn't fit above. Categorize fully later. | D13: Joint
B15: EXPENSE CATEGORIES
B16: Category Name | C16: Description | D16: Default Owner
B17: Housing | C17: Rent, mortgage, property tax, HOA, repairs, utilities tied to home. | D17: Joint
B18: Food | C18: Groceries, restaurants, coffee, food delivery. | D18: Joint
B19: Transport | C19: Car payment, gas, insurance, ride-share, public transit, flights for getting around. | D19: Joint
B20: Health | C20: Insurance, doctor visits, medication, gym, supplements, therapy. | D20: Joint
B21: Lifestyle | C21: Entertainment, hobbies, dining out experiences, recreation. | D21: Joint
B22: Travel & Adventure | C22: Vacations, trips, the Adventure List items as they actually happen. | D22: Joint
B23: Family & Kids | C23: Childcare, school, kids' activities, family-specific expenses. | D23: Joint
B24: Education | C24: Books, courses, coaching, conferences, ongoing learning. | D24: Joint
B25: Personal | C25: Clothing, grooming, personal care. | D25: Joint
B26: Subscriptions | C26: Streaming, software, memberships, recurring small charges. | D26: Joint
B27: Giving | C27: Tithing, charitable donations, foundation contributions, gifts to others. | D27: Joint
... B31: Other Expenses | C31: Anything that doesn't fit above. Categorize fully later. | D31: Joint
B33: ASSET CATEGORIES
B34: Category Name | C34: Description | D34: Default Owner
B35: Cash & Equivalents | C35: Checking, savings, money market, short-term CDs. | D35: Joint
B36: Taxable Investments | C36: Brokerage accounts, individual stocks, ETFs, mutual funds outside retirement. | D36: Joint
B37: Retirement Accounts | C37: 401(k), IRA, Roth IRA, SEP, pension. Tax-advantaged. | D37: Joint
B38: Real Estate | C38: Primary residence, rental properties, land. Use current market value. | D38: Joint
B39: Vehicles | C39: Cars, motorcycles, boats. Use current market value, not purchase price. | D39: Joint
B40: Businesses Owned | C40: Equity in businesses you own. Use estimated value. | D40: Joint
B41: Other Assets | C41: Collectibles, jewelry, anything of meaningful value not above. | D41: Joint
B43: LIABILITY CATEGORIES
B44: Category Name | C44: Description | D44: Default Owner
B45: Credit Cards | C45: Revolving credit card balances. Track each card separately. | D45: Joint
B46: Personal Loans | C46: Unsecured personal debt, lines of credit. | D46: Joint
B47: Auto Loans | C47: Loans secured by a vehicle. | D47: Joint
B48: Student Loans | C48: Education debt. | D48: Joint
...

Sheet Income Log
B2: INCOME LOG
B3: Every dollar in. 30 seconds per entry.
B5: Date | C5: Amount | D5: Owner | E5: Source / Vendor | F5: Category | G5: Year-Month | H5: Notes
B6: 46027 | C6: 6500 | D6: His | E6: Learn And Grow Rich Inc. | F6: Active Income | G6: =IF(B6="","",TEXT(B6,"YYYY-MM")) -> 2026-01 | H6: Bi-weekly paycheck
B7: 46027 | C7: 2400 | D7: Hers | E7: Sumary Consulting | F7: Active Income | G7: =IF(B7="","",TEXT(B7,"YYYY-MM")) -> 2026-01 | H7: Monthly contract
B8: 46037 | C8: 1200 | D8: Joint | E8: Rental — Apt 2B | F8: Passive Income | G8: =IF(B8="","",TEXT(B8,"YYYY-MM")) -> 2026-01 | H8: Tenant rent
B9: 46041 | C9: 6500 | D9: His | E9: Learn And Grow Rich Inc. | F9: Active Income | G9: =IF(B9="","",TEXT(B9,"YYYY-MM")) -> 2026-01 | H9: Bi-weekly paycheck
B10: 46050 | C10: 450 | D10: Hers | E10: Coaching client | F10: Side Income | G10: =IF(B10="","",TEXT(B10,"YYYY-MM")) -> 2026-01 | H10: 1:1 session block
G11: =IF(B11="","",TEXT(B11,"YYYY-MM"))
G12: =IF(B12="","",TEXT(B12,"YYYY-MM"))
G13: =IF(B13="","",TEXT(B13,"YYYY-MM"))
G14: =IF(B14="","",TEXT(B14,"YYYY-MM"))
G15: =IF(B15="","",TEXT(B15,"YYYY-MM"))
G16: =IF(B16="","",TEXT(B16,"YYYY-MM"))
G17: =IF(B17="","",TEXT(B17,"YYYY-MM"))
G18: =IF(B18="","",TEXT(B18,"YYYY-MM"))
G19: =IF(B19="","",TEXT(B19,"YYYY-MM"))
G20: =IF(B20="","",TEXT(B20,"YYYY-MM"))
G21: =IF(B21="","",TEXT(B21,"YYYY-MM"))
G22: =IF(B22="","",TEXT(B22,"YYYY-MM"))
... G205: =IF(B205="","",TEXT(B205,"YYYY-MM"))

Sheet Expense Log
B2: EXPENSE LOG
B3: Every dollar out. Same shape as income.
B5: Date | C5: Amount | D5: Owner | E5: Vendor | F5: Category | G5: Payment Method | H5: Year-Month | I5: Notes
B6: 46023 | C6: 2800 | D6: Joint | E6: Mortgage Co. | F6: Housing | G6: Auto-Pay | H6: =IF(B6="","",TEXT(B6,"YYYY-MM")) -> 2026-01 | I6: January mortgage
B7: 46025 | C7: 187.43 | D7: Hers | E7: Whole Foods | F7: Food | G7: Credit Card | H7: =IF(B7="","",TEXT(B7,"YYYY-MM")) -> 2026-01 | I7: Weekly groceries
B8: 46026 | C8: 142 | D8: His | E8: Shell | F8: Transport | G8: Credit Card | H8: =IF(B8="","",TEXT(B8,"YYYY-MM")) -> 2026-01 | I8: Gas
B9: 46028 | C9: 520 | D9: Joint | E9: Blue Cross | F9: Health | G9: Auto-Pay | H9: =IF(B9="","",TEXT(B9,"YYYY-MM")) -> 2026-01 | I9: Family insurance
B10: 46030 | C10: 54.2 | D10: Hers | E10: Trader Joe's | F10: Food | G10: Credit Card | H10: =IF(B10="","",TEXT(B10,"YYYY-MM")) -> 2026-01 | I10: Mid-week run
B11: 46032 | C11: 89 | D11: Joint | E11: Local restaurant | F11: Food | G11: Credit Card | H11: =IF(B11="","",TEXT(B11,"YYYY-MM")) -> 2026-01 | I11: Date night
B12: 46034 | C12: 240 | D12: His | E12: Coaching program | F12: Education | G12: Credit Card | H12: =IF(B12="","",TEXT(B12,"YYYY-MM")) -> 2026-01 | I12: Monthly subscription
B13: 46037 | C13: 1200 | D13: Joint | E13: Foundation by LGR | F13: Giving | G13: Bank Transfer | H13: =IF(B13="","",TEXT(B13,"YYYY-MM")) -> 2026-01 | I13: Monthly tithe
B14: 46040 | C14: 32 | D14: Hers | E14: Yoga studio | F14: Health | G14: Credit Card | H14: =IF(B14="","",TEXT(B14,"YYYY-MM")) -> 2026-01 | I14: Class pack
B15: 46042 | C15: 14.99 | D15: Joint | E15: Streaming service | F15: Subscriptions | G15: Auto-Pay | H15: =IF(B15="","",TEXT(B15,"YYYY-MM")) -> 2026-01 | I15: Movies
B16: 46044 | C16: 175 | D16: His | E16: Auto repair shop | F16: Transport | G16: Credit Card | H16: =IF(B16="","",TEXT(B16,"YYYY-MM")) -> 2026-01 | I16: Oil change + brakes
B17: 46047 | C17: 220 | D17: Hers | E17: Online course | F17: Education | G17: Credit Card | H17: =IF(B17="","",TEXT(B17,"YYYY-MM")) -> 2026-01 | I17: Personal development
B18: 46050 | C18: 145 | D18: Joint | E18: Gas + electric | F18: Housing | G18: Auto-Pay | H18: =IF(B18="","",TEXT(B18,"YYYY-MM")) -> 2026-01 | I18: Utilities
H19: =IF(B19="","",TEXT(B19,"YYYY-MM"))
H20: =IF(B20="","",TEXT(B20,"YYYY-MM"))
H21: =IF(B21="","",TEXT(B21,"YYYY-MM"))
H22: =IF(B22="","",TEXT(B22,"YYYY-MM"))
H23: =IF(B23="","",TEXT(B23,"YYYY-MM"))
H24: =IF(B24="","",TEXT(B24,"YYYY-MM"))
H25: =IF(B25="","",TEXT(B25,"YYYY-MM"))
H26: =IF(B26="","",TEXT(B26,"YYYY-MM"))
H27: =IF(B27="","",TEXT(B27,"YYYY-MM"))
H28: =IF(B28="","",TEXT(B28,"YYYY-MM"))
H29: =IF(B29="","",TEXT(B29,"YYYY-MM"))
H30: =IF(B30="","",TEXT(B30,"YYYY-MM"))
... H405: =IF(B405="","",TEXT(B405,"YYYY-MM"))

Sheet Assets Register
B2: ASSETS REGISTER
B3: What you own. Update current value monthly. The Balance Sheet pulls from here.
B5: Asset Name | C5: Owner | D5: Category | E5: Acquired | F5: Acquired Cost | G5: Current Value | H5: As-Of Date | I5: Notes
B6: Chase Checking | C6: Joint | D6: Cash & Equivalents | E6: 43831 | F6: 8500 | G6: 12400 | H6: 46053 | I6: Primary checking
B7: Ally Savings | C7: Joint | D7: Cash & Equivalents | E7: 44270 | F7: 20000 | G7: 35000 | H7: 46053 | I7: Emergency fund
B8: Fidelity Brokerage | C8: His | D8: Taxable Investments | E8: 43221 | F8: 45000 | G8: 87500 | H8: 46053 | I8: Index funds
B9: Vanguard Roth IRA | C9: Hers | D9: Retirement Accounts | E9: 43480 | F9: 12000 | G9: 28400 | H9: 46053 | I9: Annual max contributions
B10: Schwab 401k | C10: His | D10: Retirement Accounts | E10: 42156 | F10: 80000 | G10: 215000 | H10: 46053 | I10: Employer match included
B11: Primary Residence | C11: Joint | D11: Real Estate | E11: 44774 | F11: 450000 | G11: 525000 | H11: 46053 | I11: Zillow estimate
B12: Honda Pilot | C12: Joint | D12: Vehicles | E12: 45026 | F12: 42000 | G12: 32000 | H12: 46053 | I12: KBB private party
B13: Learn And Grow Rich Inc. | C13: His | D13: Businesses Owned | E13: 43101 | F13: 0 | G13: 300000 | H13: 46053 | I13: Conservative valuation

Sheet Liabilities Register
B2: LIABILITIES REGISTER
B3: What owns you. Track every loan and revolving balance.
B5: Liability Name | C5: Owner | D5: Category | E5: Original Balance | F5: Current Balance | G5: Interest Rate | H5: Min Payment | I5: As-Of Date | J5: Notes
B6: Primary Mortgage | C6: Joint | D6: Mortgages | E6: 360000 | F6: 318500 | G6: 0.0625 | H6: 2800 | I6: 46053 | J6: 30-yr fixed
B7: Chase Credit Card | C7: Joint | D7: Credit Cards | E7: 15000 | F7: 2400 | G7: 0.2199 | H7: 50 | I7: 46053 | J7: Paid in full monthly target
B8: Honda Pilot Loan | C8: Joint | D8: Auto Loans | E8: 38000 | F8: 21500 | G8: 0.0549 | H8: 720 | I8: 46053 | J8: 5-yr term

Sheet Vision His
B2: VISION TO REALITY — HIS
B3: Dream Day + Adventure List + Monthly Budget = Dream Life Number. The destination.
B5: DREAM DAY (the cost of living one perfect day)
B6: Item | C6: Cost Per Day | F6: Notes
B7: Morning routine + breakfast | C7: 25 | F7: Coffee, journaling, healthy meal
B8: Workout / movement | C8: 15 | F8: Gym, yoga, run
B9: Work — meaningful, on purpose | C9: 0 | F9: Already covered by income
B10: Lunch | C10: 30 | F10: Out or made fresh
B11: Family time / connection | C11: 20 | F11: Activities with family
B12: Evening — date, reading, rest | C12: 50 | F12: Dinner, downtime
B21: Dream Day Total | C21: =SUM(C7:C20) -> 140 | D21: × 30 days = | E21: =C21*30 -> 4200
B23: ADVENTURE LIST (the experiences you want, with cost and frequency)
B24: Adventure | C24: Cost Per Trip | D24: Per Year | E24: Annual Total | F24: Notes
B25: International trip | C25: 12000 | D25: 1 | E25: =C25*D25 -> 12000 | F25: One major trip per year
B26: Domestic weekend getaway | C26: 2500 | D26: 4 | E26: =C26*D26 -> 10000 | F26: Quarterly recharge
B27: Motorcycle adventure | C27: 3500 | D27: 2 | E27: =C27*D27 -> 7000 | F27: Solo / with friends
B28: Family vacation | C28: 8000 | D28: 1 | E28: =C28*D28 -> 8000 | F28: Annual family trip
B29: Conference / mastermind | C29: 5000 | D29: 2 | E29: =C29*D29 -> 10000 | F29: Personal growth
E30: =IF(OR(C30="",D30=""),"",C30*D30)
E31: =IF(OR(C31="",D31=""),"",C31*D31)
E32: =IF(OR(C32="",D32=""),"",C32*D32)
E33: =IF(OR(C33="",D33=""),"",C33*D33)
E34: =IF(OR(C34="",D34=""),"",C34*D34)
E35: =IF(OR(C35="",D35=""),"",C35*D35)
E36: =IF(OR(C36="",D36=""),"",C36*D36)
E37: =IF(OR(C37="",D37=""),"",C37*D37)
B38: Adventure List Annual Total | C38: =E38/12 -> 3916.6667 | D38: ÷ 12 months = | E38: =SUM(E25:E37) -> 47000
B40: MONTHLY BUDGET (the regular life — what it costs to live the way you want, every month)
B41: Category | C41: Monthly Cost | F41: Notes
B42: Housing (mortgage + utilities + maintenance) | C42: 3500 | F42: Including HOA, repairs
B43: Food | C43: 1500 | F43: Groceries + dining
B44: Transport | C44: 800 | F44: Gas, insurance, maintenance
B45: Health & wellness | C45: 600 | F45: Insurance, gym, therapy
B46: Education / coaching | C46: 500 | F46: Continuous learning
B47: Giving (10%+) | C47: 1500 | F47: Tithe + foundation
B48: Personal / lifestyle | C48: 800 | F48: Clothing, hobbies
B49: Savings / investments | C49: 3000 | F49: Pay yourself first
B56: Monthly Budget Total | C56: =SUM(C42:C55) -> 12200
B58: DREAM LIFE NUMBER
B59: Dream Day × 30 | C59: =E21 -> 4200
...

Sheet Vision Hers
B2: VISION TO REALITY — HERS
B3: Dream Day + Adventure List + Monthly Budget = Dream Life Number. The destination.
B5: DREAM DAY (the cost of living one perfect day)
B6: Item | C6: Cost Per Day | F6: Notes
B7: Morning ritual + breakfast | C7: 30 | F7: Quiet time, journaling, breakfast
B8: Movement / yoga / walk | C8: 20 | F8: Gentle daily practice
B9: Creative / fulfilling work | C9: 0 | F9: Already covered by income
B10: Lunch | C10: 25 | F10: Healthy meal
B11: Friends, family, connection | C11: 30 | F11: Coffee, lunch, calls
B12: Evening — beauty, presence, rest | C12: 60 | F12: Dinner out, self-care
B21: Dream Day Total | C21: =SUM(C7:C20) -> 165 | D21: × 30 days = | E21: =C21*30 -> 4950
B23: ADVENTURE LIST (the experiences you want, with cost and frequency)
B24: Adventure | C24: Cost Per Trip | D24: Per Year | E24: Annual Total | F24: Notes
B25: International retreat / trip | C25: 8000 | D25: 2 | E25: =C25*D25 -> 16000 | F25: Solo or girls' trip
B26: Spa weekend / wellness retreat | C26: 3000 | D26: 3 | E26: =C26*D26 -> 9000 | F26: Quarterly reset
B27: Workshop / personal growth | C27: 2500 | D27: 3 | E27: =C27*D27 -> 7500 | F27: Learning + community
B28: Family vacation | C28: 8000 | D28: 1 | E28: =C28*D28 -> 8000 | F28: Annual family trip
B29: Creative project / class | C29: 1500 | D29: 4 | E29: =C29*D29 -> 6000 | F29: Photography, writing, art
E30: =IF(OR(C30="",D30=""),"",C30*D30)
E31: =IF(OR(C31="",D31=""),"",C31*D31)
E32: =IF(OR(C32="",D32=""),"",C32*D32)
E33: =IF(OR(C33="",D33=""),"",C33*D33)
E34: =IF(OR(C34="",D34=""),"",C34*D34)
E35: =IF(OR(C35="",D35=""),"",C35*D35)
E36: =IF(OR(C36="",D36=""),"",C36*D36)
E37: =IF(OR(C37="",D37=""),"",C37*D37)
B38: Adventure List Annual Total | C38: =E38/12 -> 3875 | D38: ÷ 12 months = | E38: =SUM(E25:E37) -> 46500
B40: MONTHLY BUDGET (the regular life — what it costs to live the way you want, every month)
B41: Category | C41: Monthly Cost | F41: Notes
B42: Housing share | C42: 0 | F42: Joint covers most
B43: Personal food / dining | C43: 600 | F43: Beyond joint groceries
B44: Wellness (yoga, therapy, supplements) | C44: 800 | F44: Self-care non-negotiable
B45: Beauty / personal care | C45: 400 | F45: Ongoing investment
B46: Education / personal growth | C46: 400 | F46: Books, courses, coaching
B47: Giving | C47: 500 | F47: Personal causes
B48: Lifestyle / hobbies | C48: 600 | F48: Photography, creative
B49: Personal savings | C49: 1500 | F49: Her own runway
B56: Monthly Budget Total | C56: =SUM(C42:C55) -> 4800
B58: DREAM LIFE NUMBER
B59: Dream Day × 30 | C59: =E21 -> 4950
...

Sheet Vision Joint
B2: VISION TO REALITY — JOINT
B3: Dream Day + Adventure List + Monthly Budget = Dream Life Number. The destination.
B5: DREAM DAY (the cost of living one perfect day)
B6: Item | C6: Cost Per Day | F6: Notes
B7: Shared morning (coffee, walk together) | C7: 15 | F7: The good start
B8: Family meals | C8: 50 | F8: Real food, real time
B9: Together evenings | C9: 30 | F9: Date night cadence
B10: Weekly date out | C10: 35 | F10: Allocated daily
B19: Dream Day Total | C19: =SUM(C7:C18) -> 130 | D19: × 30 days = | E19: =C19*30 -> 3900
B21: ADVENTURE LIST (the experiences you want, with cost and frequency)
B22: Adventure | C22: Cost Per Trip | D22: Per Year | E22: Annual Total | F22: Notes
B23: Family annual vacation | C23: 12000 | D23: 1 | E23: =C23*D23 -> 12000 | F23: Big one together
B24: Couples retreat / trip | C24: 6000 | D24: 2 | E24: =C24*D24 -> 12000 | F24: Just the two of you
B25: Anniversary trip | C25: 4000 | D25: 1 | E25: =C25*D25 -> 4000 | F25: Tradition
B26: Holidays with extended family | C26: 3500 | D26: 1 | E26: =C26*D26 -> 3500 | F26: Annual gathering
E27: =IF(OR(C27="",D27=""),"",C27*D27)
E28: =IF(OR(C28="",D28=""),"",C28*D28)
E29: =IF(OR(C29="",D29=""),"",C29*D29)
E30: =IF(OR(C30="",D30=""),"",C30*D30)
E31: =IF(OR(C31="",D31=""),"",C31*D31)
E32: =IF(OR(C32="",D32=""),"",C32*D32)
E33: =IF(OR(C33="",D33=""),"",C33*D33)
E34: =IF(OR(C34="",D34=""),"",C34*D34)
B35: Adventure List Annual Total | C35: =E35/12 -> 2625 | D35: ÷ 12 months = | E35: =SUM(E23:E34) -> 31500
B37: MONTHLY BUDGET (the regular life — what it costs to live the way you want, every month)
B38: Category | C38: Monthly Cost | F38: Notes
B39: Housing (combined) | C39: 3500 | F39: Mortgage + utilities + repairs
B40: Family food | C40: 1200 | F40: Joint groceries + family dining
B41: Joint transportation | C41: 800 | F41: Family vehicle
B42: Family health insurance | C42: 800 | F42: Combined plan
B43: Family / kids | C43: 0 | F43: Update when kids arrive
B44: Joint giving | C44: 1000 | F44: Foundation contribution
B45: Joint savings | C45: 2500 | F45: Wealth building together
B52: Monthly Budget Total | C52: =SUM(C39:C51) -> 9800
B54: DREAM LIFE NUMBER
B55: Dream Day × 30 | C55: =E19 -> 3900
B56: Adventure List ÷ 12 | C56: =C35 -> 2625
B57: Monthly Budget | C57: =C52 -> 9800
B58: DREAM LIFE NUMBER — Monthly | C58: =SUM(C55:C57) -> 16325
B59: DREAM LIFE NUMBER — Annual | C59: =C58*12 -> 195900

Sheet Best Year Ever
B2: BEST YEAR EVER
B3: 10 years out, 3 years out, 1 year out, this quarter, this month, this week. The cadence that compounds.
B5: 10-YEAR VISION
B6: Where will the family be in 10 years? | C6: By 2036, we are living the path. Our kids understand money, light, and impact. Net worth past $X. Foundation funding $X/year. We are who we said we'd be.
B7: 10-Year Net Worth Target | C7: 5000000
B8: 10-Year Annual Income Target | C8: 750000
B10: 3-YEAR PICTURE
B11: What does year 3 look like? | C11: By 2029, software and training program shipped to thousands. Sumary running the personal finance arm. Joint Dream Life Number fully funded.
B12: 3-Year Net Worth Target | C12: 2000000
B13: 3-Year Annual Income Target | C13: 400000
B15: 1-YEAR GOALS (the year ahead, broken into 5 buckets)
B16: Finance | C16: Hit $X monthly after-tax income. Fund the Dream Life Number. Pay down credit cards to zero. Increase investments by $X.
B17: Lifestyle | C17: Take 2 international trips, 4 domestic. Daily Dream Day rhythm. Live the way we said we wanted to live.
B18: Relationship | C18: Weekly date night. Quarterly couple's retreat. Honest weekly money conversation.
B19: Health | C19: 5 days/week movement. Sleep 8 hours. Quarterly check-ups. No excuses.
B20: Spiritual | C20: Daily meditation. Monthly silent time. Continuous integration of light into work and home.
B22: LIMITING BELIEF REFRAMES
B23: Old belief | C23: I can't afford to give yet — I need to take care of us first.
B24: Reframe | C24: Giving multiplies what flows through me. The path to abundance is generosity.
B25: Old belief | C25: Finance is too complicated for me.
B26: Reframe | C26: Finance is replicable math. Anyone can learn it. Education is the difference.
B27: Old belief | C27: I'll figure out money once we make more.
B28: Reframe | C28: We make more by figuring out money. Not the other way around.
B30: QUARTERLY ROCKS (Q1)
B31: Rock 1 | C31: Fully populate Software by LGR with 90 days of data. Test every workflow.
B32: Rock 2 | C32: Both spouses complete Vision To Reality. Dream Life Number locked.
B33: Rock 3 | C33: Clear all credit card revolving balances.
B34: Rock 4 | C34: First 30 days of Software by LGR training program drafted.
B35: Rock 5
B37: MONTHLY CHECK-IN
B38: What worked this month?
B39: What didn't?
B40: What's the one decision I need to make next month?
B42: WEEKLY REVIEW PROMPTS
B43: What moved me toward my Dream Life Number this week?
B44: What pulled me away?
B45: What is one impact-aware decision I'll make next week?

Sheet Income Statement
B2: INCOME STATEMENT
B3: The Money Making Machine, scaled to a person. Year-to-date totals by owner.
B5: Reporting Year | C5: =Settings!$D$24 -> 2026
C6: His | D6: Hers | E6: Joint | F6: Combined
B7: GROSS INCOME
B8: Active Income | C8: =SUMIFS('Income Log'!$C$6:$C$205,'Income Log'!$D$6:$D$205,"His",'Income Log'!$F$6:$F$205,"Active Income",'Income Log'!$B$6:$B$205,">="&DATE($C$5,1,1),'Income Log'!$B$6:$B$205,"<="&DATE($C$5,12,31)) -> 13000 | D8: =SUMIFS('Income Log'!$C$6:$C$205,'Income Log'!$D$6:$D$205,"Hers",'Income Log'!$F$6:$F$205,"Active Income",'Income Log'!$B$6:$B$205,">="&DATE($C$5,1,1),'Income Log'!$B$6:$B$205,"<="&DATE($C$5,12,31)) -> 2400 | E8: =SUMIFS('Income Log'!$C$6:$C$205,'Income Log'!$D$6:$D$205,"Joint",'Income Log'!$F$6:$F$205,"Active Income",'Income Log'!$B$6:$B$205,">="&DATE($C$5,1,1),'Income Log'!$B$6:$B$205,"<="&DATE($C$5,12,31)) -> 0 | F8: =SUM(C8:E8) -> 15400
B9: Business Income | C9: =SUMIFS('Income Log'!$C$6:$C$205,'Income Log'!$D$6:$D$205,"His",'Income Log'!$F$6:$F$205,"Business Income",'Income Log'!$B$6:$B$205,">="&DATE($C$5,1,1),'Income Log'!$B$6:$B$205,"<="&DATE($C$5,12,31)) -> 0 | D9: =SUMIFS('Income Log'!$C$6:$C$205,'Income Log'!$D$6:$D$205,"Hers",'Income Log'!$F$6:$F$205,"Business Income",'Income Log'!$B$6:$B$205,">="&DATE($C$5,1,1),'Income Log'!$B$6:$B$205,"<="&DATE($C$5,12,31)) -> 0 | E9: =SUMIFS('Income Log'!$C$6:$C$205,'Income Log'!$D$6:$D$205,"Joint",'Income Log'!$F$6:$F$205,"Business Income",'Income Log'!$B$6:$B$205,">="&DATE($C$5,1,1),'Income Log'!$B$6:$B$205,"<="&DATE($C$5,12,31)) -> 0 | F9: =SUM(C9:E9) -> 0
B10: Passive Income | C10: =SUMIFS('Income Log'!$C$6:$C$205,'Income Log'!$D$6:$D$205,"His",'Income Log'!$F$6:$F$205,"Passive Income",'Income Log'!$B$6:$B$205,">="&DATE($C$5,1,1),'Income Log'!$B$6:$B$205,"<="&DATE($C$5,12,31)) -> 0 | D10: =SUMIFS('Income Log'!$C$6:$C$205,'Income Log'!$D$6:$D$205,"Hers",'Income Log'!$F$6:$F$205,"Passive Income",'Income Log'!$B$6:$B$205,">="&DATE($C$5,1,1),'Income Log'!$B$6:$B$205,"<="&DATE($C$5,12,31)) -> 0 | E10: =SUMIFS('Income Log'!$C$6:$C$205,'Income Log'!$D$6:$D$205,"Joint",'Income Log'!$F$6:$F$205,"Passive Income",'Income Log'!$B$6:$B$205,">="&DATE($C$5,1,1),'Income Log'!$B$6:$B$205,"<="&DATE($C$5,12,31)) -> 1200 | F10: =SUM(C10:E10) -> 1200
B11: Side Income | C11: =SUMIFS('Income Log'!$C$6:$C$205,'Income Log'!$D$6:$D$205,"His",'Income Log'!$F$6:$F$205,"Side Income",'Income Log'!$B$6:$B$205,">="&DATE($C$5,1,1),'Income Log'!$B$6:$B$205,"<="&DATE($C$5,12,31)) -> 0 | D11: =SUMIFS('Income Log'!$C$6:$C$205,'Income Log'!$D$6:$D$205,"Hers",'Income Log'!$F$6:$F$205,"Side Income",'Income Log'!$B$6:$B$205,">="&DATE($C$5,1,1),'Income Log'!$B$6:$B$205,"<="&DATE($C$5,12,31)) -> 450 | E11: =SUMIFS('Income Log'!$C$6:$C$205,'Income Log'!$D$6:$D$205,"Joint",'Income Log'!$F$6:$F$205,"Side Income",'Income Log'!$B$6:$B$205,">="&DATE($C$5,1,1),'Income Log'!$B$6:$B$205,"<="&DATE($C$5,12,31)) -> 0 | F11: =SUM(C11:E11) -> 450
B12: Investment Gains | C12: =SUMIFS('Income Log'!$C$6:$C$205,'Income Log'!$D$6:$D$205,"His",'Income Log'!$F$6:$F$205,"Investment Gains",'Income Log'!$B$6:$B$205,">="&DATE($C$5,1,1),'Income Log'!$B$6:$B$205,"<="&DATE($C$5,12,31)) -> 0 | D12: =SUMIFS('Income Log'!$C$6:$C$205,'Income Log'!$D$6:$D$205,"Hers",'Income Log'!$F$6:$F$205,"Investment Gains",'Income Log'!$B$6:$B$205,">="&DATE($C$5,1,1),'Income Log'!$B$6:$B$205,"<="&DATE($C$5,12,31)) -> 0 | E12: =SUMIFS('Income Log'!$C$6:$C$205,'Income Log'!$D$6:$D$205,"Joint",'Income Log'!$F$6:$F$205,"Investment Gains",'Income Log'!$B$6:$B$205,">="&DATE($C$5,1,1),'Income Log'!$B$6:$B$205,"<="&DATE($C$5,12,31)) -> 0 | F12: =SUM(C12:E12) -> 0
B13: Gifts & Windfalls | C13: =SUMIFS('Income Log'!$C$6:$C$205,'Income Log'!$D$6:$D$205,"His",'Income Log'!$F$6:$F$205,"Gifts & Windfalls",'Income Log'!$B$6:$B$205,">="&DATE($C$5,1,1),'Income Log'!$B$6:$B$205,"<="&DATE($C$5,12,31)) -> 0 | D13: =SUMIFS('Income Log'!$C$6:$C$205,'Income Log'!$D$6:$D$205,"Hers",'Income Log'!$F$6:$F$205,"Gifts & Windfalls",'Income Log'!$B$6:$B$205,">="&DATE($C$5,1,1),'Income Log'!$B$6:$B$205,"<="&DATE($C$5,12,31)) -> 0 | E13: =SUMIFS('Income Log'!$C$6:$C$205,'Income Log'!$D$6:$D$205,"Joint",'Income Log'!$F$6:$F$205,"Gifts & Windfalls",'Income Log'!$B$6:$B$205,">="&DATE($C$5,1,1),'Income Log'!$B$6:$B$205,"<="&DATE($C$5,12,31)) -> 0 | F13: =SUM(C13:E13) -> 0
B14: Other Income | C14: =SUMIFS('Income Log'!$C$6:$C$205,'Income Log'!$D$6:$D$205,"His",'Income Log'!$F$6:$F$205,"Other Income",'Income Log'!$B$6:$B$205,">="&DATE($C$5,1,1),'Income Log'!$B$6:$B$205,"<="&DATE($C$5,12,31)) -> 0 | D14: =SUMIFS('Income Log'!$C$6:$C$205,'Income Log'!$D$6:$D$205,"Hers",'Income Log'!$F$6:$F$205,"Other Income",'Income Log'!$B$6:$B$205,">="&DATE($C$5,1,1),'Income Log'!$B$6:$B$205,"<="&DATE($C$5,12,31)) -> 0 | E14: =SUMIFS('Income Log'!$C$6:$C$205,'Income Log'!$D$6:$D$205,"Joint",'Income Log'!$F$6:$F$205,"Other Income",'Income Log'!$B$6:$B$205,">="&DATE($C$5,1,1),'Income Log'!$B$6:$B$205,"<="&DATE($C$5,12,31)) -> 0 | F14: =SUM(C14:E14) -> 0
B15: TOTAL GROSS INCOME | C15: =SUM(C8:C14) -> 13000 | D15: =SUM(D8:D14) -> 2850 | E15: =SUM(E8:E14) -> 1200 | F15: =SUM(F8:F14) -> 17050
B17: EXPENSES
B18: Housing | C18: =SUMIFS('Expense Log'!$C$6:$C$405,'Expense Log'!$D$6:$D$405,"His",'Expense Log'!$F$6:$F$405,"Housing",'Expense Log'!$B$6:$B$405,">="&DATE($C$5,1,1),'Expense Log'!$B$6:$B$405,"<="&DATE($C$5,12,31)) -> 0 | D18: =SUMIFS('Expense Log'!$C$6:$C$405,'Expense Log'!$D$6:$D$405,"Hers",'Expense Log'!$F$6:$F$405,"Housing",'Expense Log'!$B$6:$B$405,">="&DATE($C$5,1,1),'Expense Log'!$B$6:$B$405,"<="&DATE($C$5,12,31)) -> 0 | E18: =SUMIFS('Expense Log'!$C$6:$C$405,'Expense Log'!$D$6:$D$405,"Joint",'Expense Log'!$F$6:$F$405,"Housing",'Expense Log'!$B$6:$B$405,">="&DATE($C$5,1,1),'Expense Log'!$B$6:$B$405,"<="&DATE($C$5,12,31)) -> 2945 | F18: =SUM(C18:E18) -> 2945
B19: Food | C19: =SUMIFS('Expense Log'!$C$6:$C$405,'Expense Log'!$D$6:$D$405,"His",'Expense Log'!$F$6:$F$405,"Food",'Expense Log'!$B$6:$B$405,">="&DATE($C$5,1,1),'Expense Log'!$B$6:$B$405,"<="&DATE($C$5,12,31)) -> 0 | D19: =SUMIFS('Expense Log'!$C$6:$C$405,'Expense Log'!$D$6:$D$405,"Hers",'Expense Log'!$F$6:$F$405,"Food",'Expense Log'!$B$6:$B$405,">="&DATE($C$5,1,1),'Expense Log'!$B$6:$B$405,"<="&DATE($C$5,12,31)) -> 241.63 | E19: =SUMIFS('Expense Log'!$C$6:$C$405,'Expense Log'!$D$6:$D$405,"Joint",'Expense Log'!$F$6:$F$405,"Food",'Expense Log'!$B$6:$B$405,">="&DATE($C$5,1,1),'Expense Log'!$B$6:$B$405,"<="&DATE($C$5,12,31)) -> 89 | F19: =SUM(C19:E19) -> 330.63
B20: Transport | C20: =SUMIFS('Expense Log'!$C$6:$C$405,'Expense Log'!$D$6:$D$405,"His",'Expense Log'!$F$6:$F$405,"Transport",'Expense Log'!$B$6:$B$405,">="&DATE($C$5,1,1),'Expense Log'!$B$6:$B$405,"<="&DATE($C$5,12,31)) -> 317 | D20: =SUMIFS('Expense Log'!$C$6:$C$405,'Expense Log'!$D$6:$D$405,"Hers",'Expense Log'!$F$6:$F$405,"Transport",'Expense Log'!$B$6:$B$405,">="&DATE($C$5,1,1),'Expense Log'!$B$6:$B$405,"<="&DATE($C$5,12,31)) -> 0 | E20: =SUMIFS('Expense Log'!$C$6:$C$405,'Expense Log'!$D$6:$D$405,"Joint",'Expense Log'!$F$6:$F$405,"Transport",'Expense Log'!$B$6:$B$405,">="&DATE($C$5,1,1),'Expense Log'!$B$6:$B$405,"<="&DATE($C$5,12,31)) -> 0 | F20: =SUM(C20:E20) -> 317
B21: Health | C21: =SUMIFS('Expense Log'!$C$6:$C$405,'Expense Log'!$D$6:$D$405,"His",'Expense Log'!$F$6:$F$405,"Health",'Expense Log'!$B$6:$B$405,">="&DATE($C$5,1,1),'Expense Log'!$B$6:$B$405,"<="&DATE($C$5,12,31)) -> 0 | D21: =SUMIFS('Expense Log'!$C$6:$C$405,'Expense Log'!$D$6:$D$405,"Hers",'Expense Log'!$F$6:$F$405,"Health",'Expense Log'!$B$6:$B$405,">="&DATE($C$5,1,1),'Expense Log'!$B$6:$B$405,"<="&DATE($C$5,12,31)) -> 32 | E21: =SUMIFS('Expense Log'!$C$6:$C$405,'Expense Log'!$D$6:$D$405,"Joint",'Expense Log'!$F$6:$F$405,"Health",'Expense Log'!$B$6:$B$405,">="&DATE($C$5,1,1),'Expense Log'!$B$6:$B$405,"<="&DATE($C$5,12,31)) -> 520 | F21: =SUM(C21:E21) -> 552
B22: Lifestyle | C22: =SUMIFS('Expense Log'!$C$6:$C$405,'Expense Log'!$D$6:$D$405,"His",'Expense Log'!$F$6:$F$405,"Lifestyle",'Expense Log'!$B$6:$B$405,">="&DATE($C$5,1,1),'Expense Log'!$B$6:$B$405,"<="&DATE($C$5,12,31)) -> 0 | D22: =SUMIFS('Expense Log'!$C$6:$C$405,'Expense Log'!$D$6:$D$405,"Hers",'Expense Log'!$F$6:$F$405,"Lifestyle",'Expense Log'!$B$6:$B$405,">="&DATE($C$5,1,1),'Expense Log'!$B$6:$B$405,"<="&DATE($C$5,12,31)) -> 0 | E22: =SUMIFS('Expense Log'!$C$6:$C$405,'Expense Log'!$D$6:$D$405,"Joint",'Expense Log'!$F$6:$F$405,"Lifestyle",'Expense Log'!$B$6:$B$405,">="&DATE($C$5,1,1),'Expense Log'!$B$6:$B$405,"<="&DATE($C$5,12,31)) -> 0 | F22: =SUM(C22:E22) -> 0
B23: Travel & Adventure | C23: =SUMIFS('Expense Log'!$C$6:$C$405,'Expense Log'!$D$6:$D$405,"His",'Expense Log'!$F$6:$F$405,"Travel & Adventure",'Expense Log'!$B$6:$B$405,">="&DATE($C$5,1,1),'Expense Log'!$B$6:$B$405,"<="&DATE($C$5,12,31)) -> 0 | D23: =SUMIFS('Expense Log'!$C$6:$C$405,'Expense Log'!$D$6:$D$405,"Hers",'Expense Log'!$F$6:$F$405,"Travel & Adventure",'Expense Log'!$B$6:$B$405,">="&DATE($C$5,1,1),'Expense Log'!$B$6:$B$405,"<="&DATE($C$5,12,31)) -> 0 | E23: =SUMIFS('Expense Log'!$C$6:$C$405,'Expense Log'!$D$6:$D$405,"Joint",'Expense Log'!$F$6:$F$405,"Travel & Adventure",'Expense Log'!$B$6:$B$405,">="&DATE($C$5,1,1),'Expense Log'!$B$6:$B$405,"<="&DATE($C$5,12,31)) -> 0 | F23: =SUM(C23:E23) -> 0
B24: Family & Kids | C24: =SUMIFS('Expense Log'!$C$6:$C$405,'Expense Log'!$D$6:$D$405,"His",'Expense Log'!$F$6:$F$405,"Family & Kids",'Expense Log'!$B$6:$B$405,">="&DATE($C$5,1,1),'Expense Log'!$B$6:$B$405,"<="&DATE($C$5,12,31)) -> 0 | D24: =SUMIFS('Expense Log'!$C$6:$C$405,'Expense Log'!$D$6:$D$405,"Hers",'Expense Log'!$F$6:$F$405,"Family & Kids",'Expense Log'!$B$6:$B$405,">="&DATE($C$5,1,1),'Expense Log'!$B$6:$B$405,"<="&DATE($C$5,12,31)) -> 0 | E24: =SUMIFS('Expense Log'!$C$6:$C$405,'Expense Log'!$D$6:$D$405,"Joint",'Expense Log'!$F$6:$F$405,"Family & Kids",'Expense Log'!$B$6:$B$405,">="&DATE($C$5,1,1),'Expense Log'!$B$6:$B$405,"<="&DATE($C$5,12,31)) -> 0 | F24: =SUM(C24:E24) -> 0
B25: Education | C25: =SUMIFS('Expense Log'!$C$6:$C$405,'Expense Log'!$D$6:$D$405,"His",'Expense Log'!$F$6:$F$405,"Education",'Expense Log'!$B$6:$B$405,">="&DATE($C$5,1,1),'Expense Log'!$B$6:$B$405,"<="&DATE($C$5,12,31)) -> 240 | D25: =SUMIFS('Expense Log'!$C$6:$C$405,'Expense Log'!$D$6:$D$405,"Hers",'Expense Log'!$F$6:$F$405,"Education",'Expense Log'!$B$6:$B$405,">="&DATE($C$5,1,1),'Expense Log'!$B$6:$B$405,"<="&DATE($C$5,12,31)) -> 220 | E25: =SUMIFS('Expense Log'!$C$6:$C$405,'Expense Log'!$D$6:$D$405,"Joint",'Expense Log'!$F$6:$F$405,"Education",'Expense Log'!$B$6:$B$405,">="&DATE($C$5,1,1),'Expense Log'!$B$6:$B$405,"<="&DATE($C$5,12,31)) -> 0 | F25: =SUM(C25:E25) -> 460
B26: Personal | C26: =SUMIFS('Expense Log'!$C$6:$C$405,'Expense Log'!$D$6:$D$405,"His",'Expense Log'!$F$6:$F$405,"Personal",'Expense Log'!$B$6:$B$405,">="&DATE($C$5,1,1),'Expense Log'!$B$6:$B$405,"<="&DATE($C$5,12,31)) -> 0 | D26: =SUMIFS('Expense Log'!$C$6:$C$405,'Expense Log'!$D$6:$D$405,"Hers",'Expense Log'!$F$6:$F$405,"Personal",'Expense Log'!$B$6:$B$405,">="&DATE($C$5,1,1),'Expense Log'!$B$6:$B$405,"<="&DATE($C$5,12,31)) -> 0 | E26: =SUMIFS('Expense Log'!$C$6:$C$405,'Expense Log'!$D$6:$D$405,"Joint",'Expense Log'!$F$6:$F$405,"Personal",'Expense Log'!$B$6:$B$405,">="&DATE($C$5,1,1),'Expense Log'!$B$6:$B$405,"<="&DATE($C$5,12,31)) -> 0 | F26: =SUM(C26:E26) -> 0
B27: Subscriptions | C27: =SUMIFS('Expense Log'!$C$6:$C$405,'Expense Log'!$D$6:$D$405,"His",'Expense Log'!$F$6:$F$405,"Subscriptions",'Expense Log'!$B$6:$B$405,">="&DATE($C$5,1,1),'Expense Log'!$B$6:$B$405,"<="&DATE($C$5,12,31)) -> 0 | D27: =SUMIFS('Expense Log'!$C$6:$C$405,'Expense Log'!$D$6:$D$405,"Hers",'Expense Log'!$F$6:$F$405,"Subscriptions",'Expense Log'!$B$6:$B$405,">="&DATE($C$5,1,1),'Expense Log'!$B$6:$B$405,"<="&DATE($C$5,12,31)) -> 0 | E27: =SUMIFS('Expense Log'!$C$6:$C$405,'Expense Log'!$D$6:$D$405,"Joint",'Expense Log'!$F$6:$F$405,"Subscriptions",'Expense Log'!$B$6:$B$405,">="&DATE($C$5,1,1),'Expense Log'!$B$6:$B$405,"<="&DATE($C$5,12,31)) -> 14.99 | F27: =SUM(C27:E27) -> 14.99
B28: Giving | C28: =SUMIFS('Expense Log'!$C$6:$C$405,'Expense Log'!$D$6:$D$405,"His",'Expense Log'!$F$6:$F$405,"Giving",'Expense Log'!$B$6:$B$405,">="&DATE($C$5,1,1),'Expense Log'!$B$6:$B$405,"<="&DATE($C$5,12,31)) -> 0 | D28: =SUMIFS('Expense Log'!$C$6:$C$405,'Expense Log'!$D$6:$D$405,"Hers",'Expense Log'!$F$6:$F$405,"Giving",'Expense Log'!$B$6:$B$405,">="&DATE($C$5,1,1),'Expense Log'!$B$6:$B$405,"<="&DATE($C$5,12,31)) -> 0 | E28: =SUMIFS('Expense Log'!$C$6:$C$405,'Expense Log'!$D$6:$D$405,"Joint",'Expense Log'!$F$6:$F$405,"Giving",'Expense Log'!$B$6:$B$405,">="&DATE($C$5,1,1),'Expense Log'!$B$6:$B$405,"<="&DATE($C$5,12,31)) -> 1200 | F28: =SUM(C28:E28) -> 1200
B29: Taxes | C29: =SUMIFS('Expense Log'!$C$6:$C$405,'Expense Log'!$D$6:$D$405,"His",'Expense Log'!$F$6:$F$405,"Taxes",'Expense Log'!$B$6:$B$405,">="&DATE($C$5,1,1),'Expense Log'!$B$6:$B$405,"<="&DATE($C$5,12,31)) -> 0 | D29: =SUMIFS('Expense Log'!$C$6:$C$405,'Expense Log'!$D$6:$D$405,"Hers",'Expense Log'!$F$6:$F$405,"Taxes",'Expense Log'!$B$6:$B$405,">="&DATE($C$5,1,1),'Expense Log'!$B$6:$B$405,"<="&DATE($C$5,12,31)) -> 0 | E29: =SUMIFS('Expense Log'!$C$6:$C$405,'Expense Log'!$D$6:$D$405,"Joint",'Expense Log'!$F$6:$F$405,"Taxes",'Expense Log'!$B$6:$B$405,">="&DATE($C$5,1,1),'Expense Log'!$B$6:$B$405,"<="&DATE($C$5,12,31)) -> 0 | F29: =SUM(C29:E29) -> 0
B30: Debt Service | C30: =SUMIFS('Expense Log'!$C$6:$C$405,'Expense Log'!$D$6:$D$405,"His",'Expense Log'!$F$6:$F$405,"Debt Service",'Expense Log'!$B$6:$B$405,">="&DATE($C$5,1,1),'Expense Log'!$B$6:$B$405,"<="&DATE($C$5,12,31)) -> 0 | D30: =SUMIFS('Expense Log'!$C$6:$C$405,'Expense Log'!$D$6:$D$405,"Hers",'Expense Log'!$F$6:$F$405,"Debt Service",'Expense Log'!$B$6:$B$405,">="&DATE($C$5,1,1),'Expense Log'!$B$6:$B$405,"<="&DATE($C$5,12,31)) -> 0 | E30: =SUMIFS('Expense Log'!$C$6:$C$405,'Expense Log'!$D$6:$D$405,"Joint",'Expense Log'!$F$6:$F$405,"Debt Service",'Expense Log'!$B$6:$B$405,">="&DATE($C$5,1,1),'Expense Log'!$B$6:$B$405,"<="&DATE($C$5,12,31)) -> 0 | F30: =SUM(C30:E30) -> 0
B31: Insurance | C31: =SUMIFS('Expense Log'!$C$6:$C$405,'Expense Log'!$D$6:$D$405,"His",'Expense Log'!$F$6:$F$405,"Insurance",'Expense Log'!$B$6:$B$405,">="&DATE($C$5,1,1),'Expense Log'!$B$6:$B$405,"<="&DATE($C$5,12,31)) -> 0 | D31: =SUMIFS('Expense Log'!$C$6:$C$405,'Expense Log'!$D$6:$D$405,"Hers",'Expense Log'!$F$6:$F$405,"Insurance",'Expense Log'!$B$6:$B$405,">="&DATE($C$5,1,1),'Expense Log'!$B$6:$B$405,"<="&DATE($C$5,12,31)) -> 0 | E31: =SUMIFS('Expense Log'!$C$6:$C$405,'Expense Log'!$D$6:$D$405,"Joint",'Expense Log'!$F$6:$F$405,"Insurance",'Expense Log'!$B$6:$B$405,">="&DATE($C$5,1,1),'Expense Log'!$B$6:$B$405,"<="&DATE($C$5,12,31)) -> 0 | F31: =SUM(C31:E31) -> 0
B32: Other Expenses | C32: =SUMIFS('Expense Log'!$C$6:$C$405,'Expense Log'!$D$6:$D$405,"His",'Expense Log'!$F$6:$F$405,"Other Expenses",'Expense Log'!$B$6:$B$405,">="&DATE($C$5,1,1),'Expense Log'!$B$6:$B$405,"<="&DATE($C$5,12,31)) -> 0 | D32: =SUMIFS('Expense Log'!$C$6:$C$405,'Expense Log'!$D$6:$D$405,"Hers",'Expense Log'!$F$6:$F$405,"Other Expenses",'Expense Log'!$B$6:$B$405,">="&DATE($C$5,1,1),'Expense Log'!$B$6:$B$405,"<="&DATE($C$5,12,31)) -> 0 | E32: =SUMIFS('Expense Log'!$C$6:$C$405,'Expense Log'!$D$6:$D$405,"Joint",'Expense Log'!$F$6:$F$405,"Other Expenses",'Expense Log'!$B$6:$B$405,">="&DATE($C$5,1,1),'Expense Log'!$B$6:$B$405,"<="&DATE($C$5,12,31)) -> 0 | F32: =SUM(C32:E32) -> 0
B33: TOTAL EXPENSES | C33: =SUM(C18:C32) -> 557 | D33: =SUM(D18:D32) -> 493.63 | E33: =SUM(E18:E32) -> 4768.99 | F33: =SUM(F18:F32) -> 5819.62
B35: NET INCOME (Pre-Tax) | C35: =C15-C33 -> 12443 | D35: =D15-D33 -> 2356.37 | E35: =E15-E33 -> -3568.99 | F35: =F15-F33 -> 11230.38
B37: Note: Taxes are treated as an expense category in this personal model. Net Income above is therefore already after-tax to the extent tax payments are logged in the Expense Log.

Sheet Cash Flow
B2: CASH FLOW STATEMENT
B3: Where the money actually went. Operations + Investing + Financing = Net change in cash.
B5: Reporting Year | C5: =Settings!$D$24 -> 2026
B7: CASH FROM OPERATIONS
B8: Total Income (all sources, all owners) | C8: ='Income Statement'!F15 -> 17050 | D8: From Income Statement, Combined column
B9: Total Operating Expenses | C9: =-'Income Statement'!F33 -> -5819.62 | D9: Negative — money out
B10: NET CASH FROM OPERATIONS | C10: =C8+C9 -> 11230.38
B12: CASH FROM INVESTING
B13: Asset Purchases (manual input — track major buys) | C13: 0 | D13: Enter as negative when buying assets
B14: Asset Sales (manual input — track major sales) | C14: 0 | D14: Enter as positive when selling assets
B15: NET CASH FROM INVESTING | C15: =C13+C14 -> 0
B17: CASH FROM FINANCING
B18: New Debt Taken On | C18: 0 | D18: Enter as positive when taking on debt
B19: Debt Principal Paid Down | C19: 0 | D19: Enter as negative when paying down debt
B20: NET CASH FROM FINANCING | C20: =C18+C19 -> 0
B22: NET CHANGE IN CASH
B23: Net Change in Cash (Operations + Investing + Financing) | C23: =C10+C15+C20 -> 11230.38

Sheet Balance Sheet
B2: BALANCE SHEET
B3: Snapshot of net worth. What you own minus what owns you.
B5: As-Of Date | C5: =TODAY() -> 46140
C6: His | D6: Hers | E6: Joint | F6: Combined
B7: ASSETS
B8: Cash & Equivalents | C8: =SUMIFS('Assets Register'!$G$6:$G$105,'Assets Register'!$C$6:$C$105,"His",'Assets Register'!$D$6:$D$105,"Cash & Equivalents") -> 0 | D8: =SUMIFS('Assets Register'!$G$6:$G$105,'Assets Register'!$C$6:$C$105,"Hers",'Assets Register'!$D$6:$D$105,"Cash & Equivalents") -> 0 | E8: =SUMIFS('Assets Register'!$G$6:$G$105,'Assets Register'!$C$6:$C$105,"Joint",'Assets Register'!$D$6:$D$105,"Cash & Equivalents") -> 47400 | F8: =SUM(C8:E8) -> 47400
B9: Taxable Investments | C9: =SUMIFS('Assets Register'!$G$6:$G$105,'Assets Register'!$C$6:$C$105,"His",'Assets Register'!$D$6:$D$105,"Taxable Investments") -> 87500 | D9: =SUMIFS('Assets Register'!$G$6:$G$105,'Assets Register'!$C$6:$C$105,"Hers",'Assets Register'!$D$6:$D$105,"Taxable Investments") -> 0 | E9: =SUMIFS('Assets Register'!$G$6:$G$105,'Assets Register'!$C$6:$C$105,"Joint",'Assets Register'!$D$6:$D$105,"Taxable Investments") -> 0 | F9: =SUM(C9:E9) -> 87500
B10: Retirement Accounts | C10: =SUMIFS('Assets Register'!$G$6:$G$105,'Assets Register'!$C$6:$C$105,"His",'Assets Register'!$D$6:$D$105,"Retirement Accounts") -> 215000 | D10: =SUMIFS('Assets Register'!$G$6:$G$105,'Assets Register'!$C$6:$C$105,"Hers",'Assets Register'!$D$6:$D$105,"Retirement Accounts") -> 28400 | E10: =SUMIFS('Assets Register'!$G$6:$G$105,'Assets Register'!$C$6:$C$105,"Joint",'Assets Register'!$D$6:$D$105,"Retirement Accounts") -> 0 | F10: =SUM(C10:E10) -> 243400
B11: Real Estate | C11: =SUMIFS('Assets Register'!$G$6:$G$105,'Assets Register'!$C$6:$C$105,"His",'Assets Register'!$D$6:$D$105,"Real Estate") -> 0 | D11: =SUMIFS('Assets Register'!$G$6:$G$105,'Assets Register'!$C$6:$C$105,"Hers",'Assets Register'!$D$6:$D$105,"Real Estate") -> 0 | E11: =SUMIFS('Assets Register'!$G$6:$G$105,'Assets Register'!$C$6:$C$105,"Joint",'Assets Register'!$D$6:$D$105,"Real Estate") -> 525000 | F11: =SUM(C11:E11) -> 525000
B12: Vehicles | C12: =SUMIFS('Assets Register'!$G$6:$G$105,'Assets Register'!$C$6:$C$105,"His",'Assets Register'!$D$6:$D$105,"Vehicles") -> 0 | D12: =SUMIFS('Assets Register'!$G$6:$G$105,'Assets Register'!$C$6:$C$105,"Hers",'Assets Register'!$D$6:$D$105,"Vehicles") -> 0 | E12: =SUMIFS('Assets Register'!$G$6:$G$105,'Assets Register'!$C$6:$C$105,"Joint",'Assets Register'!$D$6:$D$105,"Vehicles") -> 32000 | F12: =SUM(C12:E12) -> 32000
B13: Businesses Owned | C13: =SUMIFS('Assets Register'!$G$6:$G$105,'Assets Register'!$C$6:$C$105,"His",'Assets Register'!$D$6:$D$105,"Businesses Owned") -> 300000 | D13: =SUMIFS('Assets Register'!$G$6:$G$105,'Assets Register'!$C$6:$C$105,"Hers",'Assets Register'!$D$6:$D$105,"Businesses Owned") -> 0 | E13: =SUMIFS('Assets Register'!$G$6:$G$105,'Assets Register'!$C$6:$C$105,"Joint",'Assets Register'!$D$6:$D$105,"Businesses Owned") -> 0 | F13: =SUM(C13:E13) -> 300000
B14: Other Assets | C14: =SUMIFS('Assets Register'!$G$6:$G$105,'Assets Register'!$C$6:$C$105,"His",'Assets Register'!$D$6:$D$105,"Other Assets") -> 0 | D14: =SUMIFS('Assets Register'!$G$6:$G$105,'Assets Register'!$C$6:$C$105,"Hers",'Assets Register'!$D$6:$D$105,"Other Assets") -> 0 | E14: =SUMIFS('Assets Register'!$G$6:$G$105,'Assets Register'!$C$6:$C$105,"Joint",'Assets Register'!$D$6:$D$105,"Other Assets") -> 0 | F14: =SUM(C14:E14) -> 0
B15: TOTAL ASSETS | C15: =SUM(C8:C14) -> 602500 | D15: =SUM(D8:D14) -> 28400 | E15: =SUM(E8:E14) -> 604400 | F15: =SUM(F8:F14) -> 1235300
B17: LIABILITIES
B18: Credit Cards | C18: =SUMIFS('Liabilities Register'!$F$6:$F$55,'Liabilities Register'!$C$6:$C$55,"His",'Liabilities Register'!$D$6:$D$55,"Credit Cards") -> 0 | D18: =SUMIFS('Liabilities Register'!$F$6:$F$55,'Liabilities Register'!$C$6:$C$55,"Hers",'Liabilities Register'!$D$6:$D$55,"Credit Cards") -> 0 | E18: =SUMIFS('Liabilities Register'!$F$6:$F$55,'Liabilities Register'!$C$6:$C$55,"Joint",'Liabilities Register'!$D$6:$D$55,"Credit Cards") -> 2400 | F18: =SUM(C18:E18) -> 2400
B19: Personal Loans | C19: =SUMIFS('Liabilities Register'!$F$6:$F$55,'Liabilities Register'!$C$6:$C$55,"His",'Liabilities Register'!$D$6:$D$55,"Personal Loans") -> 0 | D19: =SUMIFS('Liabilities Register'!$F$6:$F$55,'Liabilities Register'!$C$6:$C$55,"Hers",'Liabilities Register'!$D$6:$D$55,"Personal Loans") -> 0 | E19: =SUMIFS('Liabilities Register'!$F$6:$F$55,'Liabilities Register'!$C$6:$C$55,"Joint",'Liabilities Register'!$D$6:$D$55,"Personal Loans") -> 0 | F19: =SUM(C19:E19) -> 0
B20: Auto Loans | C20: =SUMIFS('Liabilities Register'!$F$6:$F$55,'Liabilities Register'!$C$6:$C$55,"His",'Liabilities Register'!$D$6:$D$55,"Auto Loans") -> 0 | D20: =SUMIFS('Liabilities Register'!$F$6:$F$55,'Liabilities Register'!$C$6:$C$55,"Hers",'Liabilities Register'!$D$6:$D$55,"Auto Loans") -> 0 | E20: =SUMIFS('Liabilities Register'!$F$6:$F$55,'Liabilities Register'!$C$6:$C$55,"Joint",'Liabilities Register'!$D$6:$D$55,"Auto Loans") -> 21500 | F20: =SUM(C20:E20) -> 21500
B21: Student Loans | C21: =SUMIFS('Liabilities Register'!$F$6:$F$55,'Liabilities Register'!$C$6:$C$55,"His",'Liabilities Register'!$D$6:$D$55,"Student Loans") -> 0 | D21: =SUMIFS('Liabilities Register'!$F$6:$F$55,'Liabilities Register'!$C$6:$C$55,"Hers",'Liabilities Register'!$D$6:$D$55,"Student Loans") -> 0 | E21: =SUMIFS('Liabilities Register'!$F$6:$F$55,'Liabilities Register'!$C$6:$C$55,"Joint",'Liabilities Register'!$D$6:$D$55,"Student Loans") -> 0 | F21: =SUM(C21:E21) -> 0
B22: Mortgages | C22: =SUMIFS('Liabilities Register'!$F$6:$F$55,'Liabilities Register'!$C$6:$C$55,"His",'Liabilities Register'!$D$6:$D$55,"Mortgages") -> 0 | D22: =SUMIFS('Liabilities Register'!$F$6:$F$55,'Liabilities Register'!$C$6:$C$55,"Hers",'Liabilities Register'!$D$6:$D$55,"Mortgages") -> 0 | E22: =SUMIFS('Liabilities Register'!$F$6:$F$55,'Liabilities Register'!$C$6:$C$55,"Joint",'Liabilities Register'!$D$6:$D$55,"Mortgages") -> 318500 | F22: =SUM(C22:E22) -> 318500
B23: Business Debt | C23: =SUMIFS('Liabilities Register'!$F$6:$F$55,'Liabilities Register'!$C$6:$C$55,"His",'Liabilities Register'!$D$6:$D$55,"Business Debt") -> 0 | D23: =SUMIFS('Liabilities Register'!$F$6:$F$55,'Liabilities Register'!$C$6:$C$55,"Hers",'Liabilities Register'!$D$6:$D$55,"Business Debt") -> 0 | E23: =SUMIFS('Liabilities Register'!$F$6:$F$55,'Liabilities Register'!$C$6:$C$55,"Joint",'Liabilities Register'!$D$6:$D$55,"Business Debt") -> 0 | F23: =SUM(C23:E23) -> 0
B24: Other Liabilities | C24: =SUMIFS('Liabilities Register'!$F$6:$F$55,'Liabilities Register'!$C$6:$C$55,"His",'Liabilities Register'!$D$6:$D$55,"Other Liabilities") -> 0 | D24: =SUMIFS('Liabilities Register'!$F$6:$F$55,'Liabilities Register'!$C$6:$C$55,"Hers",'Liabilities Register'!$D$6:$D$55,"Other Liabilities") -> 0 | E24: =SUMIFS('Liabilities Register'!$F$6:$F$55,'Liabilities Register'!$C$6:$C$55,"Joint",'Liabilities Register'!$D$6:$D$55,"Other Liabilities") -> 0 | F24: =SUM(C24:E24) -> 0
B25: TOTAL LIABILITIES | C25: =SUM(C18:C24) -> 0 | D25: =SUM(D18:D24) -> 0 | E25: =SUM(E18:E24) -> 342400 | F25: =SUM(F18:F24) -> 342400
B27: NET WORTH
B28: NET WORTH (Assets − Liabilities) | C28: =C15-C25 -> 602500 | D28: =D15-D25 -> 28400 | E28: =E15-E25 -> 262000 | F28: =F15-F25 -> 892900

Sheet The Gap
B2: THE GAP
B3: Where you are vs. where you're going. The math doesn't lie. The path is built on closing the gap.
B5: WHERE YOU ARE TODAY (last 12 months)
C6: His | D6: Hers | E6: Joint | F6: Combined
B7: Annual Income (Gross) | C7: ='Income Statement'!C15 -> 13000 | D7: ='Income Statement'!D15 -> 2850 | E7: ='Income Statement'!E15 -> 1200 | F7: ='Income Statement'!F15 -> 17050
B8: Annual Expenses | C8: ='Income Statement'!C33 -> 557 | D8: ='Income Statement'!D33 -> 493.63 | E8: ='Income Statement'!E33 -> 4768.99 | F8: ='Income Statement'!F33 -> 5819.62
B9: Net Income (Annual) | C9: ='Income Statement'!C35 -> 12443 | D9: ='Income Statement'!D35 -> 2356.37 | E9: ='Income Statement'!E35 -> -3568.99 | F9: ='Income Statement'!F35 -> 11230.38
B10: Net Worth Today | C10: ='Balance Sheet'!C28 -> 602500 | D10: ='Balance Sheet'!D28 -> 28400 | E10: ='Balance Sheet'!E28 -> 262000 | F10: ='Balance Sheet'!F28 -> 892900
B12: WHERE YOU'RE GOING (Dream Life Number)
B13: Dream Life Number — Monthly | C13: ='Vision His'!C62 -> 20316.667 | D13: ='Vision Hers'!C62 -> 13625 | E13: ='Vision Joint'!C58 -> 16325 | F13: =SUM(C13:E13) -> 50266.667
B14: Dream Life Number — Annual | C14: ='Vision His'!C63 -> 243800 | D14: ='Vision Hers'!C63 -> 163500 | E14: ='Vision Joint'!C59 -> 195900 | F14: =SUM(C14:E14) -> 603200
B16: THE GAP
B17: Annual Income Today | F17: =F7 -> 17050
B18: Annual Dream Life Number | F18: =F14 -> 603200
B19: GAP TO CLOSE (Annual) | F19: =F18-F17 -> 586150
B20: Monthly Income Needed | F20: =F18/12 -> 50266.667
B22: THE FOUR LENSES — How to close the gap
B23: 1. SELL MORE: Increase income. Negotiate raise. Add side income. Build a business. Charge what you're worth.
B24: Highest leverage. Income has no ceiling.
B25: 2. SPEND LESS: Reduce expenses. Cut what doesn't matter. Keep what does.
B26: Fastest. Every $1 saved = $1 you don't need to earn.
B27: 3. PAY LESS IN TAX: Legally optimize tax structure. S-corp election. Retirement contributions. Depreciation.
B28: Often overlooked. Talk to a CPA who teaches this.
B29: 4. BUY INCOME-PRODUCING ASSETS: Real estate. Dividend stocks. Businesses. Royalties. Money that arrives without your time.
B30: The endgame. The path to never working again.

Sheet Settings
B2: SETTINGS & DROPDOWN LISTS
B3: Reference data feeding dropdowns and validation across the workbook.
B5: OWNERS | C5: INCOME CATEGORIES | D5: EXPENSE CATEGORIES | E5: PAYMENT METHODS
B6: His | C6: Active Income | D6: Housing | E6: Cash
B7: Hers | C7: Business Income | D7: Food | E7: Debit Card
B8: Joint | C8: Passive Income | D8: Transport | E8: Credit Card
C9: Side Income | D9: Health | E9: Bank Transfer
C10: Investment Gains | D10: Lifestyle | E10: Check
C11: Gifts & Windfalls | D11: Travel & Adventure | E11: Auto-Pay
C12: Other Income | D12: Family & Kids | E12: Other
D13: Education
D14: Personal
D15: Subscriptions
D16: Giving
D17: Taxes
D18: Debt Service
D19: Insurance
D20: Other Expenses
B23: ASSET CATEGORIES | C23: LIABILITY CATEGORIES | D23: REPORTING YEAR
B24: Cash & Equivalents | C24: Credit Cards | D24: 2026
B25: Taxable Investments | C25: Personal Loans
B26: Retirement Accounts | C26: Auto Loans
B27: Real Estate | C27: Student Loans
B28: Vehicles | C28: Mortgages
B29: Businesses Owned | C29: Business Debt
B30: Other Assets | C30: Other Liabilities

Sheet App_Log
A1: APP_LOG — every write the app makes lands here
A2: When you log an income or expense through Ask Zach (v1.2), or click "Test write" on the Data Connections page, a new row appears below. This tab is append-only — the app never reads from here, only writes.
A4: Timestamp | B4: Action | C4: Details | D4: Source
A5: 2026-04-28 14:00 | B5: sample | C5: This row is here to show the shape — the app appends below. | D5: template

Sheet App_Data
A1: APP_DATA — machine-readable export for Software by Learn And Grow Rich (schema v2.0)
A2: All values are formulas referencing the rich tabs. Edit those tabs; this updates automatically. The app reads this tab via OAuth (Sheets API) or as a published CSV (read-only fallback).
A4: key | B4: value | C4: notes
A5: METADATA | C5: Metadata about this export
A6: schema_version | B6: "v2.0" | C6: Bumped — now includes line-item granularity
A7: last_updated | B7: =TEXT(NOW(),"yyyy-mm-dd hh:mm") -> 2026-04-28 20:44 | C7: Auto-stamps every recalc
A8: HOUSEHOLD | C8: Household identity
A9: household_name | B9: ='Setup & Profiles'!C15 -> The Oehlmans
A10: country | B10: ='Setup & Profiles'!C9 -> USA
A11: currency | B11: ='Setup & Profiles'!C10 -> USD
A12: filing_status | B12: ='Setup & Profiles'!C11 -> Married Filing Jointly
A13: HIS | C13: Spouse 1
A14: his_name | B14: ='Setup & Profiles'!C6 -> Zach
A15: his_age | B15: ='Setup & Profiles'!C7 -> 40
A16: his_role | B16: ='Setup & Profiles'!C8 -> Founder, Learn And Grow Rich
A17: HERS | C17: Spouse 2
A18: hers_name | B18: ='Setup & Profiles'!F6 -> Sumary
A19: hers_age | B19: ='Setup & Profiles'!F7 -> 38
A20: hers_role | B20: ='Setup & Profiles'!F8 -> Co-creator
A21: DREAM_LIFE | C21: Dream Life Numbers
A22: his_dln_monthly | B22: ='The Gap'!C13 -> 20316.667
A23: his_dln_annual | B23: ='The Gap'!C14 -> 243800
A24: hers_dln_monthly | B24: ='The Gap'!D13 -> 13625
A25: hers_dln_annual | B25: ='The Gap'!D14 -> 163500
A26: joint_dln_monthly | B26: ='The Gap'!E13 -> 16325
A27: joint_dln_annual | B27: ='The Gap'!E14 -> 195900
A28: combined_dln_monthly | B28: ='The Gap'!F13 -> 50266.667
A29: combined_dln_annual | B29: ='The Gap'!F14 -> 603200 | C29: Total annual cost of the dream life
A30: CURRENT_STATE | C30: Where you are today (last 12 months)
A31: annual_income | B31: ='The Gap'!F7 -> 17050 | C31: Combined annual income
A32: annual_expenses | B32: ='The Gap'!F8 -> 5819.62 | C32: Combined annual expenses
A33: annual_net | B33: ='The Gap'!F9 -> 11230.38 | C33: Income - expenses
A34: his_annual_income | B34: ='The Gap'!C7 -> 13000
A35: hers_annual_income | B35: ='The Gap'!D7 -> 2850
A36: joint_annual_income | B36: ='The Gap'!E7 -> 1200
A37: BALANCE_SHEET_TOTALS | C37: Net worth top line
A38: total_assets | B38: ='Balance Sheet'!F15 -> 1235300
A39: total_liabilities | B39: ='Balance Sheet'!F25 -> 342400
A40: net_worth | B40: ='Balance Sheet'!F28 -> 892900
A41: his_net_worth | B41: ='Balance Sheet'!C28 -> 602500
...
